CRITICAL:root:could not obtain the current mileage for setting a reminder for vehicle 77779
2019-11-25 14:45:10,299 [CRITI ] could not obtain the current mileage for setting a reminder for vehicle 77779
CRITICAL:root:could not obtain the current mileage while updating the last reminder mileage for vehicle 77779
2019-11-25 14:45:18,711 [CRITI ] could not obtain the current mileage while updating the last reminder mileage for vehicle 77779
CRITICAL:root:failed to generate daily summary reports
2019-11-25 14:45:30,940 [CRITI ] failed to generate daily summary reports
ERROR:root:HTTPConnectionPool(host='localhost', port=5000): Max retries exceeded with url: /StandardApiAction_login.action?account=admin&password=admin (Caused by NewConnectionError('<urllib3.connection.HTTPConnection object at 0x05274590>: Failed to establish a new connection: [WinError 10061] No connection could be made because the target machine actively refused it',))
Traceback (most recent call last):
  File "C:\Users\nakamura9a\Documents\code\git\mdvr_plus\env\lib\site-packages\urllib3\connection.py", line 160, in _new_conn
    (self._dns_host, self.port), self.timeout, **extra_kw)
  File "C:\Users\nakamura9a\Documents\code\git\mdvr_plus\env\lib\site-packages\urllib3\util\connection.py", line 80, in create_connection
    raise err
  File "C:\Users\nakamura9a\Documents\code\git\mdvr_plus\env\lib\site-packages\urllib3\util\connection.py", line 70, in create_connection
    sock.connect(sa)
ConnectionRefusedError: [WinError 10061] No connection could be made because the target machine actively refused it

During handling of the above exception, another exception occurred:

Traceback (most recent call last):
  File "C:\Users\nakamura9a\Documents\code\git\mdvr_plus\env\lib\site-packages\urllib3\connectionpool.py", line 603, in urlopen
    chunked=chunked)
  File "C:\Users\nakamura9a\Documents\code\git\mdvr_plus\env\lib\site-packages\urllib3\connectionpool.py", line 355, in _make_request
    conn.request(method, url, **httplib_request_kw)
  File "C:\Python36\lib\http\client.py", line 1239, in request
    self._send_request(method, url, body, headers, encode_chunked)
  File "C:\Python36\lib\http\client.py", line 1285, in _send_request
    self.endheaders(body, encode_chunked=encode_chunked)
  File "C:\Python36\lib\http\client.py", line 1234, in endheaders
    self._send_output(message_body, encode_chunked=encode_chunked)
  File "C:\Python36\lib\http\client.py", line 1026, in _send_output
    self.send(msg)
  File "C:\Python36\lib\http\client.py", line 964, in send
    self.connect()
  File "C:\Users\nakamura9a\Documents\code\git\mdvr_plus\env\lib\site-packages\urllib3\connection.py", line 183, in connect
    conn = self._new_conn()
  File "C:\Users\nakamura9a\Documents\code\git\mdvr_plus\env\lib\site-packages\urllib3\connection.py", line 169, in _new_conn
    self, "Failed to establish a new connection: %s" % e)
urllib3.exceptions.NewConnectionError: <urllib3.connection.HTTPConnection object at 0x05274590>: Failed to establish a new connection: [WinError 10061] No connection could be made because the target machine actively refused it

During handling of the above exception, another exception occurred:

Traceback (most recent call last):
  File "C:\Users\nakamura9a\Documents\code\git\mdvr_plus\env\lib\site-packages\requests\adapters.py", line 449, in send
    timeout=timeout
  File "C:\Users\nakamura9a\Documents\code\git\mdvr_plus\env\lib\site-packages\urllib3\connectionpool.py", line 641, in urlopen
    _stacktrace=sys.exc_info()[2])
  File "C:\Users\nakamura9a\Documents\code\git\mdvr_plus\env\lib\site-packages\urllib3\util\retry.py", line 399, in increment
    raise MaxRetryError(_pool, url, error or ResponseError(cause))
urllib3.exceptions.MaxRetryError: HTTPConnectionPool(host='localhost', port=5000): Max retries exceeded with url: /StandardApiAction_login.action?account=admin&password=admin (Caused by NewConnectionError('<urllib3.connection.HTTPConnection object at 0x05274590>: Failed to establish a new connection: [WinError 10061] No connection could be made because the target machine actively refused it',))

During handling of the above exception, another exception occurred:

Traceback (most recent call last):
  File "C:\Users\nakamura9a\Documents\code\git\mdvr_plus\common\api.py", line 160, in run_daily_reports
    generate_daily_harsh_braking_summary()
  File "C:\Users\nakamura9a\Documents\code\git\mdvr_plus\reports\daily_reports.py", line 232, in generate_daily_harsh_braking_summary
    session = login()
  File "C:\Users\nakamura9a\Documents\code\git\mdvr_plus\reports\report_views.py", line 29, in login
    'password':config.conn_password
  File "C:\Users\nakamura9a\Documents\code\git\mdvr_plus\env\lib\site-packages\requests\api.py", line 75, in get
    return request('get', url, params=params, **kwargs)
  File "C:\Users\nakamura9a\Documents\code\git\mdvr_plus\env\lib\site-packages\requests\api.py", line 60, in request
    return session.request(method=method, url=url, **kwargs)
  File "C:\Users\nakamura9a\Documents\code\git\mdvr_plus\env\lib\site-packages\requests\sessions.py", line 533, in request
    resp = self.send(prep, **send_kwargs)
  File "C:\Users\nakamura9a\Documents\code\git\mdvr_plus\env\lib\site-packages\requests\sessions.py", line 646, in send
    r = adapter.send(request, **kwargs)
  File "C:\Users\nakamura9a\Documents\code\git\mdvr_plus\env\lib\site-packages\requests\adapters.py", line 516, in send
    raise ConnectionError(e, request=request)
requests.exceptions.ConnectionError: HTTPConnectionPool(host='localhost', port=5000): Max retries exceeded with url: /StandardApiAction_login.action?account=admin&password=admin (Caused by NewConnectionError('<urllib3.connection.HTTPConnection object at 0x05274590>: Failed to establish a new connection: [WinError 10061] No connection could be made because the target machine actively refused it',))
2019-11-25 14:45:30,942 [ERROR ] HTTPConnectionPool(host='localhost', port=5000): Max retries exceeded with url: /StandardApiAction_login.action?account=admin&password=admin (Caused by NewConnectionError('<urllib3.connection.HTTPConnection object at 0x05274590>: Failed to establish a new connection: [WinError 10061] No connection could be made because the target machine actively refused it',))
Traceback (most recent call last):
  File "C:\Users\nakamura9a\Documents\code\git\mdvr_plus\env\lib\site-packages\urllib3\connection.py", line 160, in _new_conn
    (self._dns_host, self.port), self.timeout, **extra_kw)
  File "C:\Users\nakamura9a\Documents\code\git\mdvr_plus\env\lib\site-packages\urllib3\util\connection.py", line 80, in create_connection
    raise err
  File "C:\Users\nakamura9a\Documents\code\git\mdvr_plus\env\lib\site-packages\urllib3\util\connection.py", line 70, in create_connection
    sock.connect(sa)
ConnectionRefusedError: [WinError 10061] No connection could be made because the target machine actively refused it

During handling of the above exception, another exception occurred:

Traceback (most recent call last):
  File "C:\Users\nakamura9a\Documents\code\git\mdvr_plus\env\lib\site-packages\urllib3\connectionpool.py", line 603, in urlopen
    chunked=chunked)
  File "C:\Users\nakamura9a\Documents\code\git\mdvr_plus\env\lib\site-packages\urllib3\connectionpool.py", line 355, in _make_request
    conn.request(method, url, **httplib_request_kw)
  File "C:\Python36\lib\http\client.py", line 1239, in request
    self._send_request(method, url, body, headers, encode_chunked)
  File "C:\Python36\lib\http\client.py", line 1285, in _send_request
    self.endheaders(body, encode_chunked=encode_chunked)
  File "C:\Python36\lib\http\client.py", line 1234, in endheaders
    self._send_output(message_body, encode_chunked=encode_chunked)
  File "C:\Python36\lib\http\client.py", line 1026, in _send_output
    self.send(msg)
  File "C:\Python36\lib\http\client.py", line 964, in send
    self.connect()
  File "C:\Users\nakamura9a\Documents\code\git\mdvr_plus\env\lib\site-packages\urllib3\connection.py", line 183, in connect
    conn = self._new_conn()
  File "C:\Users\nakamura9a\Documents\code\git\mdvr_plus\env\lib\site-packages\urllib3\connection.py", line 169, in _new_conn
    self, "Failed to establish a new connection: %s" % e)
urllib3.exceptions.NewConnectionError: <urllib3.connection.HTTPConnection object at 0x05274590>: Failed to establish a new connection: [WinError 10061] No connection could be made because the target machine actively refused it

During handling of the above exception, another exception occurred:

Traceback (most recent call last):
  File "C:\Users\nakamura9a\Documents\code\git\mdvr_plus\env\lib\site-packages\requests\adapters.py", line 449, in send
    timeout=timeout
  File "C:\Users\nakamura9a\Documents\code\git\mdvr_plus\env\lib\site-packages\urllib3\connectionpool.py", line 641, in urlopen
    _stacktrace=sys.exc_info()[2])
  File "C:\Users\nakamura9a\Documents\code\git\mdvr_plus\env\lib\site-packages\urllib3\util\retry.py", line 399, in increment
    raise MaxRetryError(_pool, url, error or ResponseError(cause))
urllib3.exceptions.MaxRetryError: HTTPConnectionPool(host='localhost', port=5000): Max retries exceeded with url: /StandardApiAction_login.action?account=admin&password=admin (Caused by NewConnectionError('<urllib3.connection.HTTPConnection object at 0x05274590>: Failed to establish a new connection: [WinError 10061] No connection could be made because the target machine actively refused it',))

During handling of the above exception, another exception occurred:

Traceback (most recent call last):
  File "C:\Users\nakamura9a\Documents\code\git\mdvr_plus\common\api.py", line 160, in run_daily_reports
    generate_daily_harsh_braking_summary()
  File "C:\Users\nakamura9a\Documents\code\git\mdvr_plus\reports\daily_reports.py", line 232, in generate_daily_harsh_braking_summary
    session = login()
  File "C:\Users\nakamura9a\Documents\code\git\mdvr_plus\reports\report_views.py", line 29, in login
    'password':config.conn_password
  File "C:\Users\nakamura9a\Documents\code\git\mdvr_plus\env\lib\site-packages\requests\api.py", line 75, in get
    return request('get', url, params=params, **kwargs)
  File "C:\Users\nakamura9a\Documents\code\git\mdvr_plus\env\lib\site-packages\requests\api.py", line 60, in request
    return session.request(method=method, url=url, **kwargs)
  File "C:\Users\nakamura9a\Documents\code\git\mdvr_plus\env\lib\site-packages\requests\sessions.py", line 533, in request
    resp = self.send(prep, **send_kwargs)
  File "C:\Users\nakamura9a\Documents\code\git\mdvr_plus\env\lib\site-packages\requests\sessions.py", line 646, in send
    r = adapter.send(request, **kwargs)
  File "C:\Users\nakamura9a\Documents\code\git\mdvr_plus\env\lib\site-packages\requests\adapters.py", line 516, in send
    raise ConnectionError(e, request=request)
requests.exceptions.ConnectionError: HTTPConnectionPool(host='localhost', port=5000): Max retries exceeded with url: /StandardApiAction_login.action?account=admin&password=admin (Caused by NewConnectionError('<urllib3.connection.HTTPConnection object at 0x05274590>: Failed to establish a new connection: [WinError 10061] No connection could be made because the target machine actively refused it',))
CRITICAL:root:could not obtain the current mileage for setting a reminder for vehicle 77779
2019-11-25 14:48:15,192 [CRITI ] could not obtain the current mileage for setting a reminder for vehicle 77779
CRITICAL:root:could not obtain the current mileage while updating the last reminder mileage for vehicle 77779
2019-11-25 14:48:23,740 [CRITI ] could not obtain the current mileage while updating the last reminder mileage for vehicle 77779
CRITICAL:root:failed to generate daily summary reports
2019-11-25 14:48:35,995 [CRITI ] failed to generate daily summary reports
ERROR:root:HTTPConnectionPool(host='localhost', port=5000): Max retries exceeded with url: /StandardApiAction_login.action?account=admin&password=admin (Caused by NewConnectionError('<urllib3.connection.HTTPConnection object at 0x0585B730>: Failed to establish a new connection: [WinError 10061] No connection could be made because the target machine actively refused it',))
Traceback (most recent call last):
  File "C:\Users\nakamura9a\Documents\code\git\mdvr_plus\env\lib\site-packages\urllib3\connection.py", line 160, in _new_conn
    (self._dns_host, self.port), self.timeout, **extra_kw)
  File "C:\Users\nakamura9a\Documents\code\git\mdvr_plus\env\lib\site-packages\urllib3\util\connection.py", line 80, in create_connection
    raise err
  File "C:\Users\nakamura9a\Documents\code\git\mdvr_plus\env\lib\site-packages\urllib3\util\connection.py", line 70, in create_connection
    sock.connect(sa)
ConnectionRefusedError: [WinError 10061] No connection could be made because the target machine actively refused it

During handling of the above exception, another exception occurred:

Traceback (most recent call last):
  File "C:\Users\nakamura9a\Documents\code\git\mdvr_plus\env\lib\site-packages\urllib3\connectionpool.py", line 603, in urlopen
    chunked=chunked)
  File "C:\Users\nakamura9a\Documents\code\git\mdvr_plus\env\lib\site-packages\urllib3\connectionpool.py", line 355, in _make_request
    conn.request(method, url, **httplib_request_kw)
  File "C:\Python36\lib\http\client.py", line 1239, in request
    self._send_request(method, url, body, headers, encode_chunked)
  File "C:\Python36\lib\http\client.py", line 1285, in _send_request
    self.endheaders(body, encode_chunked=encode_chunked)
  File "C:\Python36\lib\http\client.py", line 1234, in endheaders
    self._send_output(message_body, encode_chunked=encode_chunked)
  File "C:\Python36\lib\http\client.py", line 1026, in _send_output
    self.send(msg)
  File "C:\Python36\lib\http\client.py", line 964, in send
    self.connect()
  File "C:\Users\nakamura9a\Documents\code\git\mdvr_plus\env\lib\site-packages\urllib3\connection.py", line 183, in connect
    conn = self._new_conn()
  File "C:\Users\nakamura9a\Documents\code\git\mdvr_plus\env\lib\site-packages\urllib3\connection.py", line 169, in _new_conn
    self, "Failed to establish a new connection: %s" % e)
urllib3.exceptions.NewConnectionError: <urllib3.connection.HTTPConnection object at 0x0585B730>: Failed to establish a new connection: [WinError 10061] No connection could be made because the target machine actively refused it

During handling of the above exception, another exception occurred:

Traceback (most recent call last):
  File "C:\Users\nakamura9a\Documents\code\git\mdvr_plus\env\lib\site-packages\requests\adapters.py", line 449, in send
    timeout=timeout
  File "C:\Users\nakamura9a\Documents\code\git\mdvr_plus\env\lib\site-packages\urllib3\connectionpool.py", line 641, in urlopen
    _stacktrace=sys.exc_info()[2])
  File "C:\Users\nakamura9a\Documents\code\git\mdvr_plus\env\lib\site-packages\urllib3\util\retry.py", line 399, in increment
    raise MaxRetryError(_pool, url, error or ResponseError(cause))
urllib3.exceptions.MaxRetryError: HTTPConnectionPool(host='localhost', port=5000): Max retries exceeded with url: /StandardApiAction_login.action?account=admin&password=admin (Caused by NewConnectionError('<urllib3.connection.HTTPConnection object at 0x0585B730>: Failed to establish a new connection: [WinError 10061] No connection could be made because the target machine actively refused it',))

During handling of the above exception, another exception occurred:

Traceback (most recent call last):
  File "C:\Users\nakamura9a\Documents\code\git\mdvr_plus\common\api.py", line 160, in run_daily_reports
    generate_daily_harsh_braking_summary()
  File "C:\Users\nakamura9a\Documents\code\git\mdvr_plus\reports\daily_reports.py", line 232, in generate_daily_harsh_braking_summary
    session = login()
  File "C:\Users\nakamura9a\Documents\code\git\mdvr_plus\reports\report_views.py", line 29, in login
    'password':config.conn_password
  File "C:\Users\nakamura9a\Documents\code\git\mdvr_plus\env\lib\site-packages\requests\api.py", line 75, in get
    return request('get', url, params=params, **kwargs)
  File "C:\Users\nakamura9a\Documents\code\git\mdvr_plus\env\lib\site-packages\requests\api.py", line 60, in request
    return session.request(method=method, url=url, **kwargs)
  File "C:\Users\nakamura9a\Documents\code\git\mdvr_plus\env\lib\site-packages\requests\sessions.py", line 533, in request
    resp = self.send(prep, **send_kwargs)
  File "C:\Users\nakamura9a\Documents\code\git\mdvr_plus\env\lib\site-packages\requests\sessions.py", line 646, in send
    r = adapter.send(request, **kwargs)
  File "C:\Users\nakamura9a\Documents\code\git\mdvr_plus\env\lib\site-packages\requests\adapters.py", line 516, in send
    raise ConnectionError(e, request=request)
requests.exceptions.ConnectionError: HTTPConnectionPool(host='localhost', port=5000): Max retries exceeded with url: /StandardApiAction_login.action?account=admin&password=admin (Caused by NewConnectionError('<urllib3.connection.HTTPConnection object at 0x0585B730>: Failed to establish a new connection: [WinError 10061] No connection could be made because the target machine actively refused it',))
2019-11-25 14:48:35,995 [ERROR ] HTTPConnectionPool(host='localhost', port=5000): Max retries exceeded with url: /StandardApiAction_login.action?account=admin&password=admin (Caused by NewConnectionError('<urllib3.connection.HTTPConnection object at 0x0585B730>: Failed to establish a new connection: [WinError 10061] No connection could be made because the target machine actively refused it',))
Traceback (most recent call last):
  File "C:\Users\nakamura9a\Documents\code\git\mdvr_plus\env\lib\site-packages\urllib3\connection.py", line 160, in _new_conn
    (self._dns_host, self.port), self.timeout, **extra_kw)
  File "C:\Users\nakamura9a\Documents\code\git\mdvr_plus\env\lib\site-packages\urllib3\util\connection.py", line 80, in create_connection
    raise err
  File "C:\Users\nakamura9a\Documents\code\git\mdvr_plus\env\lib\site-packages\urllib3\util\connection.py", line 70, in create_connection
    sock.connect(sa)
ConnectionRefusedError: [WinError 10061] No connection could be made because the target machine actively refused it

During handling of the above exception, another exception occurred:

Traceback (most recent call last):
  File "C:\Users\nakamura9a\Documents\code\git\mdvr_plus\env\lib\site-packages\urllib3\connectionpool.py", line 603, in urlopen
    chunked=chunked)
  File "C:\Users\nakamura9a\Documents\code\git\mdvr_plus\env\lib\site-packages\urllib3\connectionpool.py", line 355, in _make_request
    conn.request(method, url, **httplib_request_kw)
  File "C:\Python36\lib\http\client.py", line 1239, in request
    self._send_request(method, url, body, headers, encode_chunked)
  File "C:\Python36\lib\http\client.py", line 1285, in _send_request
    self.endheaders(body, encode_chunked=encode_chunked)
  File "C:\Python36\lib\http\client.py", line 1234, in endheaders
    self._send_output(message_body, encode_chunked=encode_chunked)
  File "C:\Python36\lib\http\client.py", line 1026, in _send_output
    self.send(msg)
  File "C:\Python36\lib\http\client.py", line 964, in send
    self.connect()
  File "C:\Users\nakamura9a\Documents\code\git\mdvr_plus\env\lib\site-packages\urllib3\connection.py", line 183, in connect
    conn = self._new_conn()
  File "C:\Users\nakamura9a\Documents\code\git\mdvr_plus\env\lib\site-packages\urllib3\connection.py", line 169, in _new_conn
    self, "Failed to establish a new connection: %s" % e)
urllib3.exceptions.NewConnectionError: <urllib3.connection.HTTPConnection object at 0x0585B730>: Failed to establish a new connection: [WinError 10061] No connection could be made because the target machine actively refused it

During handling of the above exception, another exception occurred:

Traceback (most recent call last):
  File "C:\Users\nakamura9a\Documents\code\git\mdvr_plus\env\lib\site-packages\requests\adapters.py", line 449, in send
    timeout=timeout
  File "C:\Users\nakamura9a\Documents\code\git\mdvr_plus\env\lib\site-packages\urllib3\connectionpool.py", line 641, in urlopen
    _stacktrace=sys.exc_info()[2])
  File "C:\Users\nakamura9a\Documents\code\git\mdvr_plus\env\lib\site-packages\urllib3\util\retry.py", line 399, in increment
    raise MaxRetryError(_pool, url, error or ResponseError(cause))
urllib3.exceptions.MaxRetryError: HTTPConnectionPool(host='localhost', port=5000): Max retries exceeded with url: /StandardApiAction_login.action?account=admin&password=admin (Caused by NewConnectionError('<urllib3.connection.HTTPConnection object at 0x0585B730>: Failed to establish a new connection: [WinError 10061] No connection could be made because the target machine actively refused it',))

During handling of the above exception, another exception occurred:

Traceback (most recent call last):
  File "C:\Users\nakamura9a\Documents\code\git\mdvr_plus\common\api.py", line 160, in run_daily_reports
    generate_daily_harsh_braking_summary()
  File "C:\Users\nakamura9a\Documents\code\git\mdvr_plus\reports\daily_reports.py", line 232, in generate_daily_harsh_braking_summary
    session = login()
  File "C:\Users\nakamura9a\Documents\code\git\mdvr_plus\reports\report_views.py", line 29, in login
    'password':config.conn_password
  File "C:\Users\nakamura9a\Documents\code\git\mdvr_plus\env\lib\site-packages\requests\api.py", line 75, in get
    return request('get', url, params=params, **kwargs)
  File "C:\Users\nakamura9a\Documents\code\git\mdvr_plus\env\lib\site-packages\requests\api.py", line 60, in request
    return session.request(method=method, url=url, **kwargs)
  File "C:\Users\nakamura9a\Documents\code\git\mdvr_plus\env\lib\site-packages\requests\sessions.py", line 533, in request
    resp = self.send(prep, **send_kwargs)
  File "C:\Users\nakamura9a\Documents\code\git\mdvr_plus\env\lib\site-packages\requests\sessions.py", line 646, in send
    r = adapter.send(request, **kwargs)
  File "C:\Users\nakamura9a\Documents\code\git\mdvr_plus\env\lib\site-packages\requests\adapters.py", line 516, in send
    raise ConnectionError(e, request=request)
requests.exceptions.ConnectionError: HTTPConnectionPool(host='localhost', port=5000): Max retries exceeded with url: /StandardApiAction_login.action?account=admin&password=admin (Caused by NewConnectionError('<urllib3.connection.HTTPConnection object at 0x0585B730>: Failed to establish a new connection: [WinError 10061] No connection could be made because the target machine actively refused it',))
CRITICAL:root:could not obtain the current mileage for setting a reminder for vehicle 77779
2019-11-25 14:53:07,514 [CRITI ] could not obtain the current mileage for setting a reminder for vehicle 77779
CRITICAL:root:could not obtain the current mileage while updating the last reminder mileage for vehicle 77779
2019-11-25 14:53:15,954 [CRITI ] could not obtain the current mileage while updating the last reminder mileage for vehicle 77779
CRITICAL:root:failed to generate daily summary reports
2019-11-25 14:53:28,000 [CRITI ] failed to generate daily summary reports
ERROR:root:HTTPConnectionPool(host='localhost', port=5000): Max retries exceeded with url: /StandardApiAction_login.action?account=admin&password=admin (Caused by NewConnectionError('<urllib3.connection.HTTPConnection object at 0x04B75CF0>: Failed to establish a new connection: [WinError 10061] No connection could be made because the target machine actively refused it',))
Traceback (most recent call last):
  File "C:\Users\nakamura9a\Documents\code\git\mdvr_plus\env\lib\site-packages\urllib3\connection.py", line 160, in _new_conn
    (self._dns_host, self.port), self.timeout, **extra_kw)
  File "C:\Users\nakamura9a\Documents\code\git\mdvr_plus\env\lib\site-packages\urllib3\util\connection.py", line 80, in create_connection
    raise err
  File "C:\Users\nakamura9a\Documents\code\git\mdvr_plus\env\lib\site-packages\urllib3\util\connection.py", line 70, in create_connection
    sock.connect(sa)
ConnectionRefusedError: [WinError 10061] No connection could be made because the target machine actively refused it

During handling of the above exception, another exception occurred:

Traceback (most recent call last):
  File "C:\Users\nakamura9a\Documents\code\git\mdvr_plus\env\lib\site-packages\urllib3\connectionpool.py", line 603, in urlopen
    chunked=chunked)
  File "C:\Users\nakamura9a\Documents\code\git\mdvr_plus\env\lib\site-packages\urllib3\connectionpool.py", line 355, in _make_request
    conn.request(method, url, **httplib_request_kw)
  File "C:\Python36\lib\http\client.py", line 1239, in request
    self._send_request(method, url, body, headers, encode_chunked)
  File "C:\Python36\lib\http\client.py", line 1285, in _send_request
    self.endheaders(body, encode_chunked=encode_chunked)
  File "C:\Python36\lib\http\client.py", line 1234, in endheaders
    self._send_output(message_body, encode_chunked=encode_chunked)
  File "C:\Python36\lib\http\client.py", line 1026, in _send_output
    self.send(msg)
  File "C:\Python36\lib\http\client.py", line 964, in send
    self.connect()
  File "C:\Users\nakamura9a\Documents\code\git\mdvr_plus\env\lib\site-packages\urllib3\connection.py", line 183, in connect
    conn = self._new_conn()
  File "C:\Users\nakamura9a\Documents\code\git\mdvr_plus\env\lib\site-packages\urllib3\connection.py", line 169, in _new_conn
    self, "Failed to establish a new connection: %s" % e)
urllib3.exceptions.NewConnectionError: <urllib3.connection.HTTPConnection object at 0x04B75CF0>: Failed to establish a new connection: [WinError 10061] No connection could be made because the target machine actively refused it

During handling of the above exception, another exception occurred:

Traceback (most recent call last):
  File "C:\Users\nakamura9a\Documents\code\git\mdvr_plus\env\lib\site-packages\requests\adapters.py", line 449, in send
    timeout=timeout
  File "C:\Users\nakamura9a\Documents\code\git\mdvr_plus\env\lib\site-packages\urllib3\connectionpool.py", line 641, in urlopen
    _stacktrace=sys.exc_info()[2])
  File "C:\Users\nakamura9a\Documents\code\git\mdvr_plus\env\lib\site-packages\urllib3\util\retry.py", line 399, in increment
    raise MaxRetryError(_pool, url, error or ResponseError(cause))
urllib3.exceptions.MaxRetryError: HTTPConnectionPool(host='localhost', port=5000): Max retries exceeded with url: /StandardApiAction_login.action?account=admin&password=admin (Caused by NewConnectionError('<urllib3.connection.HTTPConnection object at 0x04B75CF0>: Failed to establish a new connection: [WinError 10061] No connection could be made because the target machine actively refused it',))

During handling of the above exception, another exception occurred:

Traceback (most recent call last):
  File "C:\Users\nakamura9a\Documents\code\git\mdvr_plus\common\api.py", line 160, in run_daily_reports
    generate_daily_harsh_braking_summary()
  File "C:\Users\nakamura9a\Documents\code\git\mdvr_plus\reports\daily_reports.py", line 232, in generate_daily_harsh_braking_summary
    session = login()
  File "C:\Users\nakamura9a\Documents\code\git\mdvr_plus\reports\report_views.py", line 29, in login
    'password':config.conn_password
  File "C:\Users\nakamura9a\Documents\code\git\mdvr_plus\env\lib\site-packages\requests\api.py", line 75, in get
    return request('get', url, params=params, **kwargs)
  File "C:\Users\nakamura9a\Documents\code\git\mdvr_plus\env\lib\site-packages\requests\api.py", line 60, in request
    return session.request(method=method, url=url, **kwargs)
  File "C:\Users\nakamura9a\Documents\code\git\mdvr_plus\env\lib\site-packages\requests\sessions.py", line 533, in request
    resp = self.send(prep, **send_kwargs)
  File "C:\Users\nakamura9a\Documents\code\git\mdvr_plus\env\lib\site-packages\requests\sessions.py", line 646, in send
    r = adapter.send(request, **kwargs)
  File "C:\Users\nakamura9a\Documents\code\git\mdvr_plus\env\lib\site-packages\requests\adapters.py", line 516, in send
    raise ConnectionError(e, request=request)
requests.exceptions.ConnectionError: HTTPConnectionPool(host='localhost', port=5000): Max retries exceeded with url: /StandardApiAction_login.action?account=admin&password=admin (Caused by NewConnectionError('<urllib3.connection.HTTPConnection object at 0x04B75CF0>: Failed to establish a new connection: [WinError 10061] No connection could be made because the target machine actively refused it',))
2019-11-25 14:53:28,000 [ERROR ] HTTPConnectionPool(host='localhost', port=5000): Max retries exceeded with url: /StandardApiAction_login.action?account=admin&password=admin (Caused by NewConnectionError('<urllib3.connection.HTTPConnection object at 0x04B75CF0>: Failed to establish a new connection: [WinError 10061] No connection could be made because the target machine actively refused it',))
Traceback (most recent call last):
  File "C:\Users\nakamura9a\Documents\code\git\mdvr_plus\env\lib\site-packages\urllib3\connection.py", line 160, in _new_conn
    (self._dns_host, self.port), self.timeout, **extra_kw)
  File "C:\Users\nakamura9a\Documents\code\git\mdvr_plus\env\lib\site-packages\urllib3\util\connection.py", line 80, in create_connection
    raise err
  File "C:\Users\nakamura9a\Documents\code\git\mdvr_plus\env\lib\site-packages\urllib3\util\connection.py", line 70, in create_connection
    sock.connect(sa)
ConnectionRefusedError: [WinError 10061] No connection could be made because the target machine actively refused it

During handling of the above exception, another exception occurred:

Traceback (most recent call last):
  File "C:\Users\nakamura9a\Documents\code\git\mdvr_plus\env\lib\site-packages\urllib3\connectionpool.py", line 603, in urlopen
    chunked=chunked)
  File "C:\Users\nakamura9a\Documents\code\git\mdvr_plus\env\lib\site-packages\urllib3\connectionpool.py", line 355, in _make_request
    conn.request(method, url, **httplib_request_kw)
  File "C:\Python36\lib\http\client.py", line 1239, in request
    self._send_request(method, url, body, headers, encode_chunked)
  File "C:\Python36\lib\http\client.py", line 1285, in _send_request
    self.endheaders(body, encode_chunked=encode_chunked)
  File "C:\Python36\lib\http\client.py", line 1234, in endheaders
    self._send_output(message_body, encode_chunked=encode_chunked)
  File "C:\Python36\lib\http\client.py", line 1026, in _send_output
    self.send(msg)
  File "C:\Python36\lib\http\client.py", line 964, in send
    self.connect()
  File "C:\Users\nakamura9a\Documents\code\git\mdvr_plus\env\lib\site-packages\urllib3\connection.py", line 183, in connect
    conn = self._new_conn()
  File "C:\Users\nakamura9a\Documents\code\git\mdvr_plus\env\lib\site-packages\urllib3\connection.py", line 169, in _new_conn
    self, "Failed to establish a new connection: %s" % e)
urllib3.exceptions.NewConnectionError: <urllib3.connection.HTTPConnection object at 0x04B75CF0>: Failed to establish a new connection: [WinError 10061] No connection could be made because the target machine actively refused it

During handling of the above exception, another exception occurred:

Traceback (most recent call last):
  File "C:\Users\nakamura9a\Documents\code\git\mdvr_plus\env\lib\site-packages\requests\adapters.py", line 449, in send
    timeout=timeout
  File "C:\Users\nakamura9a\Documents\code\git\mdvr_plus\env\lib\site-packages\urllib3\connectionpool.py", line 641, in urlopen
    _stacktrace=sys.exc_info()[2])
  File "C:\Users\nakamura9a\Documents\code\git\mdvr_plus\env\lib\site-packages\urllib3\util\retry.py", line 399, in increment
    raise MaxRetryError(_pool, url, error or ResponseError(cause))
urllib3.exceptions.MaxRetryError: HTTPConnectionPool(host='localhost', port=5000): Max retries exceeded with url: /StandardApiAction_login.action?account=admin&password=admin (Caused by NewConnectionError('<urllib3.connection.HTTPConnection object at 0x04B75CF0>: Failed to establish a new connection: [WinError 10061] No connection could be made because the target machine actively refused it',))

During handling of the above exception, another exception occurred:

Traceback (most recent call last):
  File "C:\Users\nakamura9a\Documents\code\git\mdvr_plus\common\api.py", line 160, in run_daily_reports
    generate_daily_harsh_braking_summary()
  File "C:\Users\nakamura9a\Documents\code\git\mdvr_plus\reports\daily_reports.py", line 232, in generate_daily_harsh_braking_summary
    session = login()
  File "C:\Users\nakamura9a\Documents\code\git\mdvr_plus\reports\report_views.py", line 29, in login
    'password':config.conn_password
  File "C:\Users\nakamura9a\Documents\code\git\mdvr_plus\env\lib\site-packages\requests\api.py", line 75, in get
    return request('get', url, params=params, **kwargs)
  File "C:\Users\nakamura9a\Documents\code\git\mdvr_plus\env\lib\site-packages\requests\api.py", line 60, in request
    return session.request(method=method, url=url, **kwargs)
  File "C:\Users\nakamura9a\Documents\code\git\mdvr_plus\env\lib\site-packages\requests\sessions.py", line 533, in request
    resp = self.send(prep, **send_kwargs)
  File "C:\Users\nakamura9a\Documents\code\git\mdvr_plus\env\lib\site-packages\requests\sessions.py", line 646, in send
    r = adapter.send(request, **kwargs)
  File "C:\Users\nakamura9a\Documents\code\git\mdvr_plus\env\lib\site-packages\requests\adapters.py", line 516, in send
    raise ConnectionError(e, request=request)
requests.exceptions.ConnectionError: HTTPConnectionPool(host='localhost', port=5000): Max retries exceeded with url: /StandardApiAction_login.action?account=admin&password=admin (Caused by NewConnectionError('<urllib3.connection.HTTPConnection object at 0x04B75CF0>: Failed to establish a new connection: [WinError 10061] No connection could be made because the target machine actively refused it',))
CRITICAL:root:could not obtain the current mileage for setting a reminder for vehicle 77779
2019-11-25 14:55:11,226 [CRITI ] could not obtain the current mileage for setting a reminder for vehicle 77779
CRITICAL:root:failed to generate daily summary reports
2019-11-25 14:55:44,896 [CRITI ] failed to generate daily summary reports
ERROR:root:Command '['wkhtmltopdf', '--encoding', 'utf8', '--quiet', 'C:\\Users\\NAKAMU~1\\AppData\\Local\\Temp\\wkhtmltopdf19kkxstf.html', 'daily_reports\\harsh-braking-summary 2019-11-25.pdf']' returned non-zero exit status 1.
Traceback (most recent call last):
  File "C:\Users\nakamura9a\Documents\code\git\mdvr_plus\common\api.py", line 160, in run_daily_reports
    generate_daily_harsh_braking_summary()
  File "C:\Users\nakamura9a\Documents\code\git\mdvr_plus\reports\daily_reports.py", line 283, in generate_daily_harsh_braking_summary
    f'harsh-braking-summary {today}.pdf')
  File "C:\Users\nakamura9a\Documents\code\git\mdvr_plus\env\lib\site-packages\wkhtmltopdf\utils.py", line 237, in render_pdf_from_template
    cover_filename=cover.filename if cover else None)
  File "C:\Users\nakamura9a\Documents\code\git\mdvr_plus\env\lib\site-packages\wkhtmltopdf\utils.py", line 166, in convert_to_pdf
    return wkhtmltopdf(pages=pages, **cmd_options)
  File "C:\Users\nakamura9a\Documents\code\git\mdvr_plus\env\lib\site-packages\wkhtmltopdf\utils.py", line 147, in wkhtmltopdf
    return check_output(ck_args, **ck_kwargs)
  File "C:\Python36\lib\subprocess.py", line 336, in check_output
    **kwargs).stdout
  File "C:\Python36\lib\subprocess.py", line 418, in run
    output=stdout, stderr=stderr)
subprocess.CalledProcessError: Command '['wkhtmltopdf', '--encoding', 'utf8', '--quiet', 'C:\\Users\\NAKAMU~1\\AppData\\Local\\Temp\\wkhtmltopdf19kkxstf.html', 'daily_reports\\harsh-braking-summary 2019-11-25.pdf']' returned non-zero exit status 1.
2019-11-25 14:55:44,897 [ERROR ] Command '['wkhtmltopdf', '--encoding', 'utf8', '--quiet', 'C:\\Users\\NAKAMU~1\\AppData\\Local\\Temp\\wkhtmltopdf19kkxstf.html', 'daily_reports\\harsh-braking-summary 2019-11-25.pdf']' returned non-zero exit status 1.
Traceback (most recent call last):
  File "C:\Users\nakamura9a\Documents\code\git\mdvr_plus\common\api.py", line 160, in run_daily_reports
    generate_daily_harsh_braking_summary()
  File "C:\Users\nakamura9a\Documents\code\git\mdvr_plus\reports\daily_reports.py", line 283, in generate_daily_harsh_braking_summary
    f'harsh-braking-summary {today}.pdf')
  File "C:\Users\nakamura9a\Documents\code\git\mdvr_plus\env\lib\site-packages\wkhtmltopdf\utils.py", line 237, in render_pdf_from_template
    cover_filename=cover.filename if cover else None)
  File "C:\Users\nakamura9a\Documents\code\git\mdvr_plus\env\lib\site-packages\wkhtmltopdf\utils.py", line 166, in convert_to_pdf
    return wkhtmltopdf(pages=pages, **cmd_options)
  File "C:\Users\nakamura9a\Documents\code\git\mdvr_plus\env\lib\site-packages\wkhtmltopdf\utils.py", line 147, in wkhtmltopdf
    return check_output(ck_args, **ck_kwargs)
  File "C:\Python36\lib\subprocess.py", line 336, in check_output
    **kwargs).stdout
  File "C:\Python36\lib\subprocess.py", line 418, in run
    output=stdout, stderr=stderr)
subprocess.CalledProcessError: Command '['wkhtmltopdf', '--encoding', 'utf8', '--quiet', 'C:\\Users\\NAKAMU~1\\AppData\\Local\\Temp\\wkhtmltopdf19kkxstf.html', 'daily_reports\\harsh-braking-summary 2019-11-25.pdf']' returned non-zero exit status 1.
CRITICAL:root:could not obtain the current mileage for setting a reminder for vehicle 77779
2019-11-25 15:02:45,034 [CRITI ] could not obtain the current mileage for setting a reminder for vehicle 77779
CRITICAL:root:failed to generate daily summary reports
2019-11-25 15:03:17,834 [CRITI ] failed to generate daily summary reports
ERROR:root:Command '['wkhtmltopdf', '--encoding', 'utf8', '--quiet', 'C:\\Users\\NAKAMU~1\\AppData\\Local\\Temp\\wkhtmltopdf4lfpibqq.html', 'daily_reports\\harsh-braking-summary 2019-11-25.pdf']' returned non-zero exit status 1.
Traceback (most recent call last):
  File "C:\Users\nakamura9a\Documents\code\git\mdvr_plus\common\api.py", line 160, in run_daily_reports
    generate_daily_harsh_braking_summary()
  File "C:\Users\nakamura9a\Documents\code\git\mdvr_plus\reports\daily_reports.py", line 283, in generate_daily_harsh_braking_summary
    f'harsh-braking-summary {today}.pdf')
  File "C:\Users\nakamura9a\Documents\code\git\mdvr_plus\env\lib\site-packages\wkhtmltopdf\utils.py", line 237, in render_pdf_from_template
    cover_filename=cover.filename if cover else None)
  File "C:\Users\nakamura9a\Documents\code\git\mdvr_plus\env\lib\site-packages\wkhtmltopdf\utils.py", line 166, in convert_to_pdf
    return wkhtmltopdf(pages=pages, **cmd_options)
  File "C:\Users\nakamura9a\Documents\code\git\mdvr_plus\env\lib\site-packages\wkhtmltopdf\utils.py", line 147, in wkhtmltopdf
    return check_output(ck_args, **ck_kwargs)
  File "C:\Python36\lib\subprocess.py", line 336, in check_output
    **kwargs).stdout
  File "C:\Python36\lib\subprocess.py", line 418, in run
    output=stdout, stderr=stderr)
subprocess.CalledProcessError: Command '['wkhtmltopdf', '--encoding', 'utf8', '--quiet', 'C:\\Users\\NAKAMU~1\\AppData\\Local\\Temp\\wkhtmltopdf4lfpibqq.html', 'daily_reports\\harsh-braking-summary 2019-11-25.pdf']' returned non-zero exit status 1.
2019-11-25 15:03:17,835 [ERROR ] Command '['wkhtmltopdf', '--encoding', 'utf8', '--quiet', 'C:\\Users\\NAKAMU~1\\AppData\\Local\\Temp\\wkhtmltopdf4lfpibqq.html', 'daily_reports\\harsh-braking-summary 2019-11-25.pdf']' returned non-zero exit status 1.
Traceback (most recent call last):
  File "C:\Users\nakamura9a\Documents\code\git\mdvr_plus\common\api.py", line 160, in run_daily_reports
    generate_daily_harsh_braking_summary()
  File "C:\Users\nakamura9a\Documents\code\git\mdvr_plus\reports\daily_reports.py", line 283, in generate_daily_harsh_braking_summary
    f'harsh-braking-summary {today}.pdf')
  File "C:\Users\nakamura9a\Documents\code\git\mdvr_plus\env\lib\site-packages\wkhtmltopdf\utils.py", line 237, in render_pdf_from_template
    cover_filename=cover.filename if cover else None)
  File "C:\Users\nakamura9a\Documents\code\git\mdvr_plus\env\lib\site-packages\wkhtmltopdf\utils.py", line 166, in convert_to_pdf
    return wkhtmltopdf(pages=pages, **cmd_options)
  File "C:\Users\nakamura9a\Documents\code\git\mdvr_plus\env\lib\site-packages\wkhtmltopdf\utils.py", line 147, in wkhtmltopdf
    return check_output(ck_args, **ck_kwargs)
  File "C:\Python36\lib\subprocess.py", line 336, in check_output
    **kwargs).stdout
  File "C:\Python36\lib\subprocess.py", line 418, in run
    output=stdout, stderr=stderr)
subprocess.CalledProcessError: Command '['wkhtmltopdf', '--encoding', 'utf8', '--quiet', 'C:\\Users\\NAKAMU~1\\AppData\\Local\\Temp\\wkhtmltopdf4lfpibqq.html', 'daily_reports\\harsh-braking-summary 2019-11-25.pdf']' returned non-zero exit status 1.
CRITICAL:root:could not obtain the current mileage for setting a reminder for vehicle 77779
2019-11-25 15:04:03,986 [CRITI ] could not obtain the current mileage for setting a reminder for vehicle 77779
CRITICAL:root:failed to generate daily summary reports
2019-11-25 15:04:36,871 [CRITI ] failed to generate daily summary reports
ERROR:root:Command '['wkhtmltopdf', '--encoding', 'utf8', '--quiet', 'C:\\Users\\NAKAMU~1\\AppData\\Local\\Temp\\wkhtmltopdfukg4apq1.html', 'daily_reports\\harsh-braking-summary 2019-11-25.pdf']' returned non-zero exit status 1.
Traceback (most recent call last):
  File "C:\Users\nakamura9a\Documents\code\git\mdvr_plus\common\api.py", line 160, in run_daily_reports
    generate_daily_harsh_braking_summary()
  File "C:\Users\nakamura9a\Documents\code\git\mdvr_plus\reports\daily_reports.py", line 283, in generate_daily_harsh_braking_summary
    f'harsh-braking-summary {today}.pdf')
  File "C:\Users\nakamura9a\Documents\code\git\mdvr_plus\env\lib\site-packages\wkhtmltopdf\utils.py", line 237, in render_pdf_from_template
    cover_filename=cover.filename if cover else None)
  File "C:\Users\nakamura9a\Documents\code\git\mdvr_plus\env\lib\site-packages\wkhtmltopdf\utils.py", line 166, in convert_to_pdf
    return wkhtmltopdf(pages=pages, **cmd_options)
  File "C:\Users\nakamura9a\Documents\code\git\mdvr_plus\env\lib\site-packages\wkhtmltopdf\utils.py", line 147, in wkhtmltopdf
    return check_output(ck_args, **ck_kwargs)
  File "C:\Python36\lib\subprocess.py", line 336, in check_output
    **kwargs).stdout
  File "C:\Python36\lib\subprocess.py", line 418, in run
    output=stdout, stderr=stderr)
subprocess.CalledProcessError: Command '['wkhtmltopdf', '--encoding', 'utf8', '--quiet', 'C:\\Users\\NAKAMU~1\\AppData\\Local\\Temp\\wkhtmltopdfukg4apq1.html', 'daily_reports\\harsh-braking-summary 2019-11-25.pdf']' returned non-zero exit status 1.
2019-11-25 15:04:36,871 [ERROR ] Command '['wkhtmltopdf', '--encoding', 'utf8', '--quiet', 'C:\\Users\\NAKAMU~1\\AppData\\Local\\Temp\\wkhtmltopdfukg4apq1.html', 'daily_reports\\harsh-braking-summary 2019-11-25.pdf']' returned non-zero exit status 1.
Traceback (most recent call last):
  File "C:\Users\nakamura9a\Documents\code\git\mdvr_plus\common\api.py", line 160, in run_daily_reports
    generate_daily_harsh_braking_summary()
  File "C:\Users\nakamura9a\Documents\code\git\mdvr_plus\reports\daily_reports.py", line 283, in generate_daily_harsh_braking_summary
    f'harsh-braking-summary {today}.pdf')
  File "C:\Users\nakamura9a\Documents\code\git\mdvr_plus\env\lib\site-packages\wkhtmltopdf\utils.py", line 237, in render_pdf_from_template
    cover_filename=cover.filename if cover else None)
  File "C:\Users\nakamura9a\Documents\code\git\mdvr_plus\env\lib\site-packages\wkhtmltopdf\utils.py", line 166, in convert_to_pdf
    return wkhtmltopdf(pages=pages, **cmd_options)
  File "C:\Users\nakamura9a\Documents\code\git\mdvr_plus\env\lib\site-packages\wkhtmltopdf\utils.py", line 147, in wkhtmltopdf
    return check_output(ck_args, **ck_kwargs)
  File "C:\Python36\lib\subprocess.py", line 336, in check_output
    **kwargs).stdout
  File "C:\Python36\lib\subprocess.py", line 418, in run
    output=stdout, stderr=stderr)
subprocess.CalledProcessError: Command '['wkhtmltopdf', '--encoding', 'utf8', '--quiet', 'C:\\Users\\NAKAMU~1\\AppData\\Local\\Temp\\wkhtmltopdfukg4apq1.html', 'daily_reports\\harsh-braking-summary 2019-11-25.pdf']' returned non-zero exit status 1.
CRITICAL:root:could not obtain the current mileage for setting a reminder for vehicle 1000
2019-11-25 15:04:41,367 [CRITI ] could not obtain the current mileage for setting a reminder for vehicle 1000
CRITICAL:root:could not obtain the current mileage for setting a reminder for vehicle 1000
2019-11-25 15:05:14,091 [CRITI ] could not obtain the current mileage for setting a reminder for vehicle 1000
CRITICAL:root:could not obtain the current mileage for setting a reminder for vehicle 77779
2019-11-25 15:07:57,588 [CRITI ] could not obtain the current mileage for setting a reminder for vehicle 77779
CRITICAL:root:failed to generate daily summary reports
2019-11-25 15:08:30,704 [CRITI ] failed to generate daily summary reports
ERROR:root:Command '['wkhtmltopdf', '--encoding', 'utf8', '--quiet', 'C:\\Users\\NAKAMU~1\\AppData\\Local\\Temp\\wkhtmltopdfpqozypma.html', 'daily_reports\\harsh-braking-summary 2019-11-25.pdf']' returned non-zero exit status 1.
Traceback (most recent call last):
  File "C:\Users\nakamura9a\Documents\code\git\mdvr_plus\common\api.py", line 160, in run_daily_reports
    generate_daily_harsh_braking_summary()
  File "C:\Users\nakamura9a\Documents\code\git\mdvr_plus\reports\daily_reports.py", line 283, in generate_daily_harsh_braking_summary
    f'harsh-braking-summary {today}.pdf')
  File "c:\users\nakamura9a\documents\code\git\mdvr_plus\env\lib\site-packages\wkhtmltopdf\utils.py", line 237, in render_pdf_from_template
    cover_filename=cover.filename if cover else None)
  File "c:\users\nakamura9a\documents\code\git\mdvr_plus\env\lib\site-packages\wkhtmltopdf\utils.py", line 166, in convert_to_pdf
    return wkhtmltopdf(pages=pages, **cmd_options)
  File "c:\users\nakamura9a\documents\code\git\mdvr_plus\env\lib\site-packages\wkhtmltopdf\utils.py", line 147, in wkhtmltopdf
    return check_output(ck_args, **ck_kwargs)
  File "C:\Python36\lib\subprocess.py", line 336, in check_output
    **kwargs).stdout
  File "C:\Python36\lib\subprocess.py", line 418, in run
    output=stdout, stderr=stderr)
subprocess.CalledProcessError: Command '['wkhtmltopdf', '--encoding', 'utf8', '--quiet', 'C:\\Users\\NAKAMU~1\\AppData\\Local\\Temp\\wkhtmltopdfpqozypma.html', 'daily_reports\\harsh-braking-summary 2019-11-25.pdf']' returned non-zero exit status 1.
2019-11-25 15:08:30,704 [ERROR ] Command '['wkhtmltopdf', '--encoding', 'utf8', '--quiet', 'C:\\Users\\NAKAMU~1\\AppData\\Local\\Temp\\wkhtmltopdfpqozypma.html', 'daily_reports\\harsh-braking-summary 2019-11-25.pdf']' returned non-zero exit status 1.
Traceback (most recent call last):
  File "C:\Users\nakamura9a\Documents\code\git\mdvr_plus\common\api.py", line 160, in run_daily_reports
    generate_daily_harsh_braking_summary()
  File "C:\Users\nakamura9a\Documents\code\git\mdvr_plus\reports\daily_reports.py", line 283, in generate_daily_harsh_braking_summary
    f'harsh-braking-summary {today}.pdf')
  File "c:\users\nakamura9a\documents\code\git\mdvr_plus\env\lib\site-packages\wkhtmltopdf\utils.py", line 237, in render_pdf_from_template
    cover_filename=cover.filename if cover else None)
  File "c:\users\nakamura9a\documents\code\git\mdvr_plus\env\lib\site-packages\wkhtmltopdf\utils.py", line 166, in convert_to_pdf
    return wkhtmltopdf(pages=pages, **cmd_options)
  File "c:\users\nakamura9a\documents\code\git\mdvr_plus\env\lib\site-packages\wkhtmltopdf\utils.py", line 147, in wkhtmltopdf
    return check_output(ck_args, **ck_kwargs)
  File "C:\Python36\lib\subprocess.py", line 336, in check_output
    **kwargs).stdout
  File "C:\Python36\lib\subprocess.py", line 418, in run
    output=stdout, stderr=stderr)
subprocess.CalledProcessError: Command '['wkhtmltopdf', '--encoding', 'utf8', '--quiet', 'C:\\Users\\NAKAMU~1\\AppData\\Local\\Temp\\wkhtmltopdfpqozypma.html', 'daily_reports\\harsh-braking-summary 2019-11-25.pdf']' returned non-zero exit status 1.
CRITICAL:root:could not obtain the current mileage for setting a reminder for vehicle 1000
2019-11-25 15:08:37,005 [CRITI ] could not obtain the current mileage for setting a reminder for vehicle 1000
CRITICAL:root:could not obtain the current mileage for setting a reminder for vehicle 1000
2019-11-25 15:09:13,916 [CRITI ] could not obtain the current mileage for setting a reminder for vehicle 1000
CRITICAL:root:could not obtain the current mileage for setting a reminder for vehicle 77779
2019-11-25 15:20:33,762 [CRITI ] could not obtain the current mileage for setting a reminder for vehicle 77779
CRITICAL:root:failed to generate daily harsh braking report
2019-11-25 15:21:06,813 [CRITI ] failed to generate daily harsh braking report
ERROR:root:Command '['wkhtmltopdf', '--encoding', 'utf8', '--quiet', 'C:\\Users\\NAKAMU~1\\AppData\\Local\\Temp\\wkhtmltopdfjdkin9gt.html', 'daily_reports\\harsh-braking-summary 2019-11-25.pdf']' returned non-zero exit status 1.
Traceback (most recent call last):
  File "C:\Users\nakamura9a\Documents\code\git\mdvr_plus\common\api.py", line 160, in run_daily_reports
    generate_daily_harsh_braking_summary()
  File "C:\Users\nakamura9a\Documents\code\git\mdvr_plus\reports\daily_reports.py", line 283, in generate_daily_harsh_braking_summary
    f'harsh-braking-summary {today}.pdf')
  File "c:\users\nakamura9a\documents\code\git\mdvr_plus\env\lib\site-packages\wkhtmltopdf\utils.py", line 237, in render_pdf_from_template
    cover_filename=cover.filename if cover else None)
  File "c:\users\nakamura9a\documents\code\git\mdvr_plus\env\lib\site-packages\wkhtmltopdf\utils.py", line 166, in convert_to_pdf
    return wkhtmltopdf(pages=pages, **cmd_options)
  File "c:\users\nakamura9a\documents\code\git\mdvr_plus\env\lib\site-packages\wkhtmltopdf\utils.py", line 147, in wkhtmltopdf
    return check_output(ck_args, **ck_kwargs)
  File "C:\Python36\lib\subprocess.py", line 336, in check_output
    **kwargs).stdout
  File "C:\Python36\lib\subprocess.py", line 418, in run
    output=stdout, stderr=stderr)
subprocess.CalledProcessError: Command '['wkhtmltopdf', '--encoding', 'utf8', '--quiet', 'C:\\Users\\NAKAMU~1\\AppData\\Local\\Temp\\wkhtmltopdfjdkin9gt.html', 'daily_reports\\harsh-braking-summary 2019-11-25.pdf']' returned non-zero exit status 1.
2019-11-25 15:21:06,813 [ERROR ] Command '['wkhtmltopdf', '--encoding', 'utf8', '--quiet', 'C:\\Users\\NAKAMU~1\\AppData\\Local\\Temp\\wkhtmltopdfjdkin9gt.html', 'daily_reports\\harsh-braking-summary 2019-11-25.pdf']' returned non-zero exit status 1.
Traceback (most recent call last):
  File "C:\Users\nakamura9a\Documents\code\git\mdvr_plus\common\api.py", line 160, in run_daily_reports
    generate_daily_harsh_braking_summary()
  File "C:\Users\nakamura9a\Documents\code\git\mdvr_plus\reports\daily_reports.py", line 283, in generate_daily_harsh_braking_summary
    f'harsh-braking-summary {today}.pdf')
  File "c:\users\nakamura9a\documents\code\git\mdvr_plus\env\lib\site-packages\wkhtmltopdf\utils.py", line 237, in render_pdf_from_template
    cover_filename=cover.filename if cover else None)
  File "c:\users\nakamura9a\documents\code\git\mdvr_plus\env\lib\site-packages\wkhtmltopdf\utils.py", line 166, in convert_to_pdf
    return wkhtmltopdf(pages=pages, **cmd_options)
  File "c:\users\nakamura9a\documents\code\git\mdvr_plus\env\lib\site-packages\wkhtmltopdf\utils.py", line 147, in wkhtmltopdf
    return check_output(ck_args, **ck_kwargs)
  File "C:\Python36\lib\subprocess.py", line 336, in check_output
    **kwargs).stdout
  File "C:\Python36\lib\subprocess.py", line 418, in run
    output=stdout, stderr=stderr)
subprocess.CalledProcessError: Command '['wkhtmltopdf', '--encoding', 'utf8', '--quiet', 'C:\\Users\\NAKAMU~1\\AppData\\Local\\Temp\\wkhtmltopdfjdkin9gt.html', 'daily_reports\\harsh-braking-summary 2019-11-25.pdf']' returned non-zero exit status 1.
CRITICAL:root:could not obtain the current mileage for setting a reminder for vehicle 1000
2019-11-25 15:21:11,230 [CRITI ] could not obtain the current mileage for setting a reminder for vehicle 1000
CRITICAL:root:could not obtain the current mileage for setting a reminder for vehicle 1000
2019-11-25 15:21:47,897 [CRITI ] could not obtain the current mileage for setting a reminder for vehicle 1000
